<?xml version="1.0"?>
<robot name="wheel" xmlns:xacro="http://www.ros.org/wiki/xacro">
    <!-- Begin - Include -->
    <xacro:include filename="$(find rover_desc_pkg)/urdf/robot_parameters.xacro"/>
    <xacro:include filename="$(find rover_desc_pkg)/urdf/links_joints.xacro"/>
    <!-- End - Include -->

    <xacro:macro name="wheel" params="fb ls parent translateX translateY flipY"> <!-- fb: front, back; ls: left, right -->
        <link name="${fb}_{ls}_wheel">
            <visual>
                <origin xyz="0 0 0" rpy="${flipY*M_PI/2} 0 0"/>
                <geometry>
                    <cylinder length="${wheel_height}" radius="${wheel_radius}"/>
                </geometry>
                <material name="DarkGrey"/>

                <collision>
                    <origin xyz="0 0 0" rpy="${flipY*M_PI/2} 0 0"/>
                    <geometry>
                        <cylinder length="${wheel_height}" radius="${wheel_radius}"/>
                    </geometry>
                </collision>

                <inertial>
                    <origin xyz="0 0 0"/>
                    <mass value="${wheel_mass}"/>
                    <cylinder_inertia m="${wheel_mass}" r="${wheel_radius}" h="${wheel_height}"/>
                </inertial>
            </visual>
        </link>

        <joint name="${fb}_{ls}_wheel_joint" type="continuous">
            <parent link="${parent}"/>
            <child link="${fb}_{lr}_wheel"/>
            <origin xyz="${translateX * base_x_origin_to_wheel_origin}
                         ${translateY * base_y_origin_to_wheel_origin}
                         ${base_z_origin_to_wheel_origin}" rpy="0 0 0"/>
            <axis xyz="0 1 0" rpy="0 0 0"/>
            <limit effort="100" velocity="100"/>
            <joint_properties damping="0.0" friction="0.0"/>
        </joint>

        <!-- Transmission is important to link the joints and the controller -->
        <transmission name="${fb}_${lr}_wheel_joint_trans">
            <type>transmission_interface/SimpleTransmission</type>
            <joint name="${fb}_${lr}_wheel_joint"/>
            <actuator name="${fb}_{lr}_wheel_joint_motor">
                <hardwareInterface>EffortJointInterface</hardwareInterface>
                <mechanicalReduction>1</mechanicalReduction>
            </actuator>
        </transmission>
    </xacro:macro>
</robot>
